Traceback (most recent call last):
  File "/home/runner/.cache/pypoetry/virtualenvs/rekko-handbook-y_Nwlfrq-py3.9/lib/python3.9/site-packages/jupyter_cache/executors/utils.py", line 58, in single_nb_execution
    executenb(
  File "/home/runner/.cache/pypoetry/virtualenvs/rekko-handbook-y_Nwlfrq-py3.9/lib/python3.9/site-packages/nbclient/client.py", line 1204, in execute
    return NotebookClient(nb=nb, resources=resources, km=km, **kwargs).execute()
  File "/home/runner/.cache/pypoetry/virtualenvs/rekko-handbook-y_Nwlfrq-py3.9/lib/python3.9/site-packages/nbclient/util.py", line 84, in wrapped
    return just_run(coro(*args, **kwargs))
  File "/home/runner/.cache/pypoetry/virtualenvs/rekko-handbook-y_Nwlfrq-py3.9/lib/python3.9/site-packages/nbclient/util.py", line 62, in just_run
    return loop.run_until_complete(coro)
  File "/opt/hostedtoolcache/Python/3.9.16/x64/lib/python3.9/asyncio/base_events.py", line 647, in run_until_complete
    return future.result()
  File "/home/runner/.cache/pypoetry/virtualenvs/rekko-handbook-y_Nwlfrq-py3.9/lib/python3.9/site-packages/nbclient/client.py", line 663, in async_execute
    await self.async_execute_cell(
  File "/home/runner/.cache/pypoetry/virtualenvs/rekko-handbook-y_Nwlfrq-py3.9/lib/python3.9/site-packages/nbclient/client.py", line 965, in async_execute_cell
    await self._check_raise_for_error(cell, cell_index, exec_reply)
  File "/home/runner/.cache/pypoetry/virtualenvs/rekko-handbook-y_Nwlfrq-py3.9/lib/python3.9/site-packages/nbclient/client.py", line 862, in _check_raise_for_error
    raise CellExecutionError.from_cell_and_msg(cell, exec_reply_content)
nbclient.exceptions.CellExecutionError: An error occurred while executing the following cell:
------------------
local_test_preds = local_test_preds.explode('item_id')
local_test_preds['rank'] = local_test_preds.groupby('user_id').cumcount() + 1 
local_test_preds['item_name'] = local_test_preds['item_id'].map(item_name_mapper)
print(f'Data shape{local_test_preds.shape}')
test_preds.head()
------------------

[0;31m---------------------------------------------------------------------------[0m
[0;31mNameError[0m                                 Traceback (most recent call last)
Cell [0;32mIn[32], line 5[0m
[1;32m      3[0m local_test_preds[[38;5;124m'[39m[38;5;124mitem_name[39m[38;5;124m'[39m] [38;5;241m=[39m local_test_preds[[38;5;124m'[39m[38;5;124mitem_id[39m[38;5;124m'[39m][38;5;241m.[39mmap(item_name_mapper)
[1;32m      4[0m [38;5;28mprint[39m([38;5;124mf[39m[38;5;124m'[39m[38;5;124mData shape[39m[38;5;132;01m{[39;00mlocal_test_preds[38;5;241m.[39mshape[38;5;132;01m}[39;00m[38;5;124m'[39m)
[0;32m----> 5[0m [43mtest_preds[49m[38;5;241m.[39mhead()

[0;31mNameError[0m: name 'test_preds' is not defined
NameError: name 'test_preds' is not defined

